Workbook

Sheet AGENTS SALES 2026
A1: P.O DATE | B1: AGENT | C1: Client Company Name | D1: GOVT /PRIVATE | E1: GOODS/ CALIBRATION | F1: Amount | G1: P.O reference | H1: SERVED /NOT SERVED | I1: Principal | J1: Item Description /Inquiry of Goods/ Services | K1: WITH CALIBRATION CERTIFICATE EXPIRY | L1: BIR/COR | M1: ADDRESS | N1: Contact No. | O1: Contact Person | P1: Qoutation Control No. | Q1: SALES INVOICE | R1: SALES INVOICE DATE | S1: DR | T1: PAYMENT TERMS | U1: REMARKS | V1: Qoutation Control No. | W1: Amount | X1: NOA DATE | Y1: NTP DATE | Z1: CONTRACT
A2: 46029 | B2: MICA | C2: INNO CONS SOLUTIONS HOLDINGS,INC. | D2: PRIVATE | E2: GOODS | F2: 2600 | J2: NEOPRENE/RUBBER PAD 6" DIA | M2: Manila East Road, Brgy. Burgos Pakil Laguna/ Email: jcpakil2023@gmail.com
A3: 46049 | B3: MICA | C3: RIECKERMANN PHILIPPINES, INC. | D3: PRIVATE | E3: GOODS | F3: 122300 | G3: RPO-26-7545 | I3: LOCAL | J3: CYLINDER MOLD 4X8 | L3: 004-963-829-000 | M3: 215 Jaime Cardinal Sin St. Cor. Dela Paz Pleasant Hills Mandaluyong City | N3: (632) 8634-2623 to 26 /manila@riekermann.com | O3: ANA GOJOL/SALES SECRETARY | P3: GEI-GDS-26-2626 | T3: COD | AE3: =F2+F3+F5+F6+F7+F8+F9+F10+F11+F12+F13+F14+F15 -> 7028400
A4: 46042 | B4: MICA | C4: ALTEO ENGINEERING CONSULTANCY SERVICES | D4: PRIVATE | E4: CALIBRATION | F4: 4500 | G4: 2026-002 | J4: COMPRESSION | M4: LTO Compound, Brgy.1 Calamba, Laguna | N4: 0969-307-9505/ lab.alteoengineering@gmail.com | O4: Lovely Millanes | T4: COD
A5: 46037 | B5: MICA | C5: CONCRETE MASTERS INC. | D5: PRIVATE | E5: CALIBRATION | F5: 4000 | G5: 3569 | J5: ELECTRIC MOTOR BAGGER MIXER | L5: 005-295-683 | M5: AFP-RSBS Industrial Park, Km.12 East Service Road Corner C5 Road, Western Bicutan, Taguig City / Suha,San Mateo, Norzagaray
A6: 46034 | B6: MICA | C6: ACCIONA CONSTRUCTION S.A & EEI CORPORATION | D6: PRIVATE | E6: CALIBRATION | F6: 44000 | G6: 1922.1 | J6: BATCHING PLANT | M6: Manila East Road, Brgy. Burgos Pakil Laguna/ Email: jcpakil2023@gmail.com | T6: COD
A7: 46028 | B7: MICA | C7: METRO MANILA 1ST DEO | D7: GOV'T | E7: GOODS | F7: 106000 | G7: 2025-11-059 | J7: EXTENSION ROD & DCP
A8: 46034 | B8: MICA | C8: DPWH Sultan Kudarat 1st DEO | D8: GOV'T | E8: GOODS | F8: 1120200 | G8: 2025-12-0079 | J8: Various | M8: Department of Public Works and Highways Sultan Kudarat 1st District Engineering Office | T8: 30 days | W8: 46374 | X8: - | Y8: 60 DAYS
A9: 46028 | B9: MICA | C9: DPWH Quezon 4th DEO Gumaca Quezon Region IV-A | D9: GOV'T | E9: GOODS | F9: 1280100 | G9: 2025-12-079 | J9: Various | M9: Department of Public Works and Highways Quezon 4th District Engineering Office | T9: 30 days
A10: 46036 | B10: MICA | C10: Provincial Government of Antique | D10: GOV'T | E10: GOODS | F10: 1980500 | G10: IB NO. K-2025-274 | I10: TBTSCIETECH NANJING | J10: UTM 1000KN | T10: 60 days
A11: 46028 | B11: MICA | C11: DPWH QUEZON 2ND DEO LUCENA | D11: GOV'T | E11: GOODS | F11: 1427900 | G11: 2025-12-0260 | I11: Matest | J11: SPILL KIT, MICROMETER, SLUMPCONE | M11: Department of Public Works and Highways Quezon 2nd District Engineering Office Dalahican Road, Ibabang Dupay,Lucena City Quezon
A12: 46065 | B12: MICA | C12: SUPLICO CONSTRUCTION CORPORATION | D12: PRIVATE | E12: GOODS | F12: 280000 | G12: Purchase Order 5402 | J12: Various | L12: 008-569-218-000
A13: 46071 | B13: MICA | C13: TERAGRAIL GEOLOGY AND GEOTECHNICS | D13: PRIVATE | E13: GOODS | F13: 140000 | G13: TGGPO-2026-031 | I13: LOCAL | J13: LA MACHINE | L13: 605-416-155-000 | M13: Manila East Road, Brgy. Burgos Pakil Laguna/ Email: jcpakil2023@gmail.com
A14: 46071 | B14: MICA | C14: TERAGRAIL GEOLOGY AND GEOTECHNICS | D14: PRIVATE | E14: CALIBRATION | F14: 79800 | G14: TGGPO-2026-031 | J14: VARIOUS | L14: 605-416-155-000 | M14: 3F NO 13 LUNA ST. PINAGBUKLOD PH4,BPS,IMUS CAVITE | N14: 02 5155412/ 908 636 5350
A15: 46073 | B15: MICA | C15: ACCIONA CONSTRUCTION S.A & EEI CORPORATION | D15: PRIVATE | E15: CALIBRATION | F15: 441000 | G15: PO2175 | J15: BATCHING PLANT | M15: Blk 1 Lot 36 CITHIHOMES Subd. Manuyo Uno Las Pinas | N15: 09171384031 | O15: sir jeb karl | S15: COD
A16: 46072 | B16: MICA | C16: LANDISCO | D16: PRIVATE | E16: GOODS | F16: 8500 | G16: 0551
A17: 46092 | B17: MICA | C17: COLEGIO DE LA PURISMA CONCEPCION | D17: PRIVATE | E17: GOODS | F17: 1575000 | G17: 005077 | J17: UTM TBT 1000
A18: 46038 | B18: JCC | C18: DPWH-PANGASINAN 4TH DEO-PO2025-12-042 | D18: GOV'T | E18: GOODS | F18: 131000 | G18: PO2025-12-042
A19: 46042 | B19: JCC | C19: DPWH-DAVAO DEL SUR DEO | D19: GOV'T | E19: GOODS | F19: 784000 | G19: 25GLD00077
A20: 46029 | B20: HOUSE | C20: FREYSSINET INTERNATIONAL MANILA INC. | D20: PRIVATE | E20: CALIBRATION | F20: 8000 | G20: PO0235-MENARD MICT-20260107 | I20: X | J20: Callibration of Unconfined Compression Machine "YTW-2S" | L20: 008-165-085 | M20: Unit B and C, 16TH Floor,8751 Bdo Equitable Tower Paseo De Roxas Makati City | N20: 632 (832-8243): (832-8246)
A21: 46030 | B21: HOUSE | C21: SEHOCA CONCRETE SUPPLY | D21: PRIVATE | E21: GOODS | F21: 106000 | G21: Purchased Order #01 | I21: NL SCIENTIFIC MALAYSIA | J21: Laboratory Oven & Digital Balance NL 7017X/1003N | M21: Calamba City Laguna
A22: 46031 | B22: HOUSE | C22: SEHOCA CONCRETE SUPPLY | D22: PRIVATE | E22: CALIBRATION | F22: 23000 | G22: Purchased Order #02 | J22: Batching Plant,water cement,aggregates,Asphalt, Admixture | M22: Calamba City Laguna
A23: 46030 | B23: HOUSE | C23: ECOLOMA TRADING INTERNATIONAL CORPORATION | D23: PRIVATE | E23: GOODS | F23: 11400 | G23: P.O-2026-01-0004 | I23: DUAL USA | J23: SIEVE #14 & #3
A24: 46029 | B24: HOUSE | C24: TRI-PHIL INTERNATIONAL,INC. | D24: PRIVATE | E24: CALIBRATION | F24: 18000 | G24: P26-00032 | I24: GOTECH | J24: MODEL: AI-3000 | L24: 000-412-827-000 | M24: B1 L6, R.M. Tiosejo Industrial Complex, Bo. Tunasan, muntinlupa City, Philippines | Y24: COD (COMPANY CHEQUE)
A25: 46028 | B25: HOUSE | C25: EQUIPARCO CONSTRUCTION COMPANY | D25: PRIVATE | E25: GOODS | F25: 36000 | G25: #131874 | I25: LOCAL | J25: Calcium Carbide 500g | M25: P-3 Ambangan Ambago Butuan City | Y25: 30 days
A26: 46028 | B26: HOUSE | C26: MONOLITHIC CONSTRUCTION CONCRETE INC. | D26: PRIVATE | E26: CALIBRATION | F26: 20000 | G26: GEI-CAL2026-2205 | I26: X | J26: Stressing Jack | L26: 745-438-584 | M26: 119 Chesnut Drive Ecoland Phase 7, Matina Davao City
A27: 46050 | B27: HOUSE | C27: STX ENTERPRISES | D27: PRIVATE | E27: GOODS | F27: 45000 | G27: ABP102-812 | I27: NL SCIENTIFIC MALAYSIA | J27: Marshall Water Bath NL 2008X/002 | L27: 134-826-717-000 | M27: 607 Birmingham St. Cor. Northwood St. Metropolis Village II, Brgy. Sta Lucia. Pasig City, 1608 | V27: #004304 | W27: 46057 | Y27: COD (COMPANY CHEQUE)
A28: 46051 | B28: HOUSE | C28: PAN PACIFIC | D28: PRIVATE | E28: GOODS | F28: 950000 | G28: PPRPPC PO20226-002
A29: 46049 | B29: HOUSE | C29: TOYO-SHIMIZU JOINT VENTURE | D29: PRIVATE | E29: GOODS | F29: 15000 | G29: Ref. No. PRP4-2601-169 | I29: LOCAL | J29: Calcium Carbide 500g | L29: 600-300-210-000 | M29: 3F Planters Products Building, 109 Esteban St., Legaspi Village Makati City (delivery address: Noah Paper Mills Brgy. Kalumpang, Marikina City (Beside SM Marikina)
A30: 46044 | B30: HOUSE | C30: READYCON | D30: PRIVATE | E30: CALIBRATION | F30: 4500 | G30: PO 10109258 | J30: AIRMETER humbolt brand | M30: #407 A Rodriguez Avenue,Manggahan Pasig City Manila | N30: 997-79-59/584-5572/584-9823 | O30: CJ
A31: 46041 | B31: HOUSE | C31: GHCB PHIL CORPORATION | D31: PRIVATE | E31: CALIBRATION | F31: 9000 | G31: GEI-CAL2026-2226 | J31: TBT-COMPRESSION 2000KN | M31: Sitio Tuba Lubayat Real Quezon SB RIAD 1 Project 6 Quezon City | N31: 9480818536 | O31: ROGER DOMOLOG
A32: 46038 | B32: HOUSE | C32: READYCON | D32: PRIVATE | E32: CALIBRATION | F32: 2500 | G32: PO 10108973 | J32: Digital Platform | M32: #407 A Rodriguez Avenue,Manggahan Pasig City Manila | N32: 997-79-59/584-5572/584-9823 | O32: CJ
A33: 46035 | B33: HOUSE | C33: SMCC PHILIPPINES, INC. (SUMITOMO MITSUI CONSTRUCTION CO. GROUP) | D33: PRIVATE | E33: GOODS | F33: 6300 | G33: SMS25-S-437 | I33: TAIWAN | J33: CAPSTONE GYPSUM S420 | L33: 004-813-382-00000 | M33: 10TH Floor Frabelle Corporate Plaza 129 Tordesillas cor. Bautista St. Salcedo Village, Bel Air 1209, City of Makati | O33: MOBY WIN ABRIGANA
A34: 46027 | B34: HOUSE | C34: READYCON | D34: PRIVATE | E34: CALIBRATION | F34: 4000 | G34: PO 10108448 | J34: Caliper controls | M34: #407 A Rodriguez Avenue,Manggahan Pasig City Manila | N34: 997-79-59/584-5572/584-9823 | O34: CJ
A35: 46043 | B35: HOUSE | C35: PCON INTERNATIONAL CORP. | D35: PRIVATE | E35: GOODS | F35: 70000 | G35: QT SERVED AS P.O | J35: LENGTH COMPARATOR | L35: 655-489-023-00000 | M35: LOOBAN I LOMA DE GATO 3019 MARILAO BULACAN PHILIPPINES | O35: ENGR CARLO | P35: GEI-GDS-2026-12591 revised
A36: 46079 | B36: HOUSE | C36: RFAELDAN CONSTRUCTION SERVICES CO. | D36: PRIVATE | E36: CALIBRATION | F36: 39285.71 | G36: 2026-019 | J36: MONOSTRESSING JACK 30 TONS | M36: UNIT 204 AJBEL BLDG 9127 SAN ANTONIO AVENUE, SAN ANTONIO AVENUE VALLEY 1 PARANAQUE CITY | N36: Nancy D. Dolot RFCSC 09493414877 | P36: GEI CAL 2026-2305
A37: 46079 | B37: HOUSE | C37: SOIL PHILIPPINES INDEX TESTING INC. | D37: PRIVATE | E37: GOODS | F37: 5000 | G37: 1056 | J37: SIEVE 1/4 | O37: SIR GARY VILLABOY
A38: 46079 | B38: HOUSE | C38: READYCON | D38: PRIVATE | E38: GOODS | F38: 24000 | G38: PO 10110203 | I38: EHWA KOREA | J38: COREBIT 4" | M38: #407 A Rodriguez Avenue,Manggahan Pasig City Manila | N38: Mobile No: 0926-6554082 / 0923-0846461 Tel: (632) 646-2186 to 89 Fax: 646-2181 | O38: SHERYL R. BANAS | T38: COD
A39: 46077 | B39: HOUSE | C39: ERODMA READY-MIX CONCRETE CO. | D39: PRIVATE | E39: CALIBRATION | F39: 34900 | G39: 26-10370 | J39: Compression ,oven, sieve | M39: 219 P. DELA CRUZ ST., BRGY. SAN BARTOLOME NOVALICHES, QUEZON CITY | T39: COD
A40: 46077 | B40: HOUSE | C40: MDC CONCRETE INC | D40: PRIVATE | E40: Goods | F40: 129000 | G40: 4900163973 | J40: Various | L40: 008-593-531-000 | M40: 10/F MDC Corporate Center, Radian St.Western Bicutan Taguig City,1630 | N40: Telephone No. 02-7759-0800
...

Sheet Overall Sales
D2: JANUARY | E2: FEBRUARY | F2: MARCH | G2: APRIL | H2: MAY | I2: JUNE | J2: JULY | K2: AUGUST | L2: SEPTEMBER | M2: OCTOBER | N2: NOVEMBER | O2: DECEMBER
A3: JCC | B3: Goods | C3: Private | D3: ='AGENTS SALES 2026'!F18+'AGENTS SALES 2026'!F19 -> 915000 | P3: =SUM(D3:O3) -> 915000
C4: Government
B5: Calibration | C5: Private
C6: Government
D7: =SUM(D3:D6) -> 915000 | P7: =SUM(D7:O7) -> 915000
A8: JOVAN | B8: Goods | C8: Private
C9: Government
B10: Calibration | C10: Private
C11: Government
P12: =SUM(D12:O12) -> 0
A13: SHIELLA | B13: Goods | C13: Private | D13: ='AGENTS SALES 2026'!F70 -> 1587400 | F13: ='AGENTS SALES 2026'!F67+'AGENTS SALES 2026'!F68+'AGENTS SALES 2026'!F66 -> 1106000 | P13: =SUM(D13:O13) -> 2693400
C14: Government | D14: ='AGENTS SALES 2026'!F69 -> 1802890 | P14: =SUM(D14:O14) -> 1802890
B15: Calibration | C15: Private | P15: =SUM(D15:O15) -> 0
C16: Government | P16: =SUM(D16:O16) -> 0
D17: =SUM(D13:D16) -> 3390290 | F17: =SUM(F13:F16) -> 1106000 | P17: =SUM(D17:O17) -> 4496290
A18: MICA | B18: Goods | C18: Private | D18: ='AGENTS SALES 2026'!F2+'AGENTS SALES 2026'!F3 -> 124900 | E18: ='AGENTS SALES 2026'!F12+'AGENTS SALES 2026'!F13 -> 420000 | F18: ='AGENTS SALES 2026'!F16+'AGENTS SALES 2026'!F17 -> 1583500 | P18: =SUM(D18:O18) -> 2128400
C19: Government | D19: ='AGENTS SALES 2026'!F7+'AGENTS SALES 2026'!F8+'AGENTS SALES 2026'!F9+'AGENTS SALES 2026'!F10+'AGENTS SALES 2026'!F11 -> 5914700 | E19: 0 | P19: =SUM(D19:O19) -> 5914700
B20: Calibration | C20: Private | D20: ='AGENTS SALES 2026'!F5+'AGENTS SALES 2026'!F6 -> 48000 | E20: ='AGENTS SALES 2026'!F14+'AGENTS SALES 2026'!F15 -> 520800 | P20: =SUM(D20:O20) -> 568800
C21: Government
D22: =SUM(D18:D21) -> 6087600 | E22: =SUM(E18:E21) -> 940800 | F22: =SUM(F18:F20) -> 1583500 | P22: =SUM(D22:O22) -> 8611900
A23: ROBERT | B23: Goods | C23: Private
C24: Government | D24: 149000 | E24: ='AGENTS SALES 2026'!F63+'AGENTS SALES 2026'!F64 -> 22300 | P24: =SUM(D24:O24) -> 171300
B25: Calibration | C25: Private | D25: 0 | P25: =SUM(D25:O25) -> 0
C26: Government | D26: ='AGENTS SALES 2026'!F61 -> 22000 | P26: =SUM(D26:O26) -> 22000
D27: =SUM(D24:D26) -> 171000 | E27: =SUM(E24:E26) -> 22300 | P27: =SUM(D27:O27) -> 193300
A28: HOUSE | B28: Goods | C28: Private | D28: ='AGENTS SALES 2026'!F21+'AGENTS SALES 2026'!F23+'AGENTS SALES 2026'!F25+'AGENTS SALES 2026'!F27+'AGENTS SALES 2026'!F28+'AGENTS SALES 2026'!F29+'AGENTS SALES 2026'!F33+'AGENTS SALES 2026'!F35 -> 1239700 | E28: ='AGENTS SALES 2026'!F37+'AGENTS SALES 2026'!F38+'AGENTS SALES 2026'!F40+'AGENTS SALES 2026'!F41+'AGENTS SALES 2026'!F42+'AGENTS SALES 2026'!F43+'AGENTS SALES 2026'!F46+'AGENTS SALES 2026'!F47+'AGENTS SALES 2026'!F48+'AGENTS SALES 2026'!F50+'AGENTS SALES 2026'!F52+'AGENTS SALES 2026'!F53 -> 1652249.6 | F28: ='AGENTS SALES 2026'!F55+'AGENTS SALES 2026'!F56+'AGENTS SALES 2026'!F57+'AGENTS SALES 2026'!F58 -> 1235991.4 | P28: =SUM(D28:O28) -> 4127941.1
C29: Government
B30: Calibration | C30: Private | D30: ='AGENTS SALES 2026'!F20+'AGENTS SALES 2026'!F22+'AGENTS SALES 2026'!F24+'AGENTS SALES 2026'!F26++'AGENTS SALES 2026'!F30+'AGENTS SALES 2026'!F31+'AGENTS SALES 2026'!F32+'AGENTS SALES 2026'!F34+'AGENTS SALES 2026'!F71 -> 93000 | E30: ='AGENTS SALES 2026'!F36+'AGENTS SALES 2026'!F39+'AGENTS SALES 2026'!F71+'AGENTS SALES 2026'!F44+'AGENTS SALES 2026'!F45+'AGENTS SALES 2026'!F49+'AGENTS SALES 2026'!F51 -> 160485.71 | F30: ='AGENTS SALES 2026'!F54 -> 8500 | P30: =SUM(D30:O30) -> 261985.71
C31: Government
D32: =SUM(D28:D31) -> 1332700 | E32: =SUM(E28:E31) -> 1812735.4 | F32: =SUM(F28:F30) -> 1244491.4 | P32: =SUM(D32:O32) -> 4389926.8
A34: KTS | B34: Goods | C34: Private
C35: Government
B36: Calibration | C36: Private
C37: Government
A39: BTC | B39: Goods | C39: Private | D39: ='AGENTS SALES 2026'!F60 -> 232000 | F39: ='AGENTS SALES 2026'!F59 -> 89000 | P39: =SUM(D39:O39) -> 321000
C40: Government
B41: Calibration | C41: Private
C42: Government
D43: =SUM(D39:D42) -> 232000 | F43: =SUM(F39:F42) -> 89000 | P43: =SUM(D43:O43) -> 321000
...

Sheet pau-accomplishment
B5: Accomplishment | I5: Accomplishment | M5: Remarks
B6: PROSPECTIVE CLIENTS | D6: CONTACT NUMBER / PERSON | F6: LOCATION
B7: FUGRO PHILIPPINES INC. | D7: Ms.Lizette Fugro ('09175626103) | F7: Unit 303A, Taipan Place Bldg. Ortigas Center | M7: with connection to philinstrument
B8: PHILINSTRUMENT CORP | D8: Ms.Lizette Gabriel (09283957527) lisetteg.pic@yahoo.com | F8: 3F J Rimando Bldg 1706 E Rod Sr. Cubao QC
B9: AVM ENGINEERING GEOTECHNICAL AND MATERIALS TESTING SERVICES | D9: Christvan Aporado Owner (09178610615) | F9: 23 Col Divino Sto,Brgy.Sto Nino, Marikina
B10: ADVANCED GEOTECHNICAL ENGINEERING SERVICES (AGES) | D10: Engr. Justin Edward V. Tan (09178518280) Main Office (Quezon City): * Landline: +63 (2) 7903-3965 / (02) 8939-6368 Mobile: +63 917-851-8280 / +63 922-880-0967 ages@ages.ph Cebu Office: Landline: (032) 261-2994 / (032) 264-6433 Mobile: +63 917-896-3164 | F10: Address: 103 Dunhill St., East Fairview, Quezon City 1118
B11: Ready Mix Concrete | D11: (+63) 999-886-4132 / (+63) 917-885-4370 mgs.readymix@mgs.com.ph
B12: EXAN BUILDERS | D12: Head Office 72 Int. C. Santos St. Evangelista Ave., Santolan, Pasig City 646 – 5806 / 646 – 1008 681 – 2223 / 681 – 2224 sales@exanbuilders.com
B13: MEGA TESTING CENTER,INC. (QUEZON CITY) | D13: 09190807104 /(02)8289-8305 | F13: #26 CONGRESSIONAL AVENUE, BAHAY TORO QUEZON CITY Region Branch/Office Address NCR Main
B14: E.B TESTING CENTER | D14: Main Office (QC) Christine Dayenne Quiñones (02) 8930-5839 / 8930-5971 ebtestingcenter.qc@gmail.com Pasig Branch Kelvin G. Panganiban (02) 633-6098 / 0925-5217686 ebtestingcenter.pasig@gmail.com Luzon Branches Urdaneta (Pangasinan): (075) 632-7364 Isabela: (078) 324-6176 / 0917-702-5014 | ebtci_isabela@yahoo.com Naga City: (054) 881-8897 / 0925-7622280 | ebtci.naga@yahoo.com Visayas Branches Cebu City: (032) 402-0598 / 0917-5085328 | ebtesting_cebu@yahoo.com Bohol (Tagbilaran): (038) 500-9002 / 0917-6328508 | ebtcibohol@yahoo.com Tacloban: (053) 832-0148 | ebtci_tacloban@yahoo.com Mindanao Branches Davao City: (082) 227-5398 / 0917-6314365 | ebtestingdavao@gmail.com CDO / Misamis: 0977-1128648 | ebtci_cdo@yahoo.com Koronadal: (083) 553-6410 / 0926-3214121 | ebtcikoronadal@gmail.com | F14: E. Bolivar Building, No. 10 P. Burgos Cor. F. Calderon St., Brgy. Marilag, Project 4, Quezon City.
B16: TARGET FOR FEBRUARY 16-20, 2026 | I16: Accomplishment | M16: Remarks
B17: PROSPECTIVE CLIENTS | D17: CONTACT NUMBER / PERSON | F17: LOCATION
A18: government | B18: DENR MINES & GEOSCIENCE BUREAU | D18: andreafayebelen@gmail.com / Andrea Faye T. Belen Engineer III MGB - Metallurgical Technology Division /09661762164 | I18: VIA GMAIL EMAILED AND CALLED 2/19/2026
A19: private | B19: EM CUERPO INC. | D19: emcuerpo.purchasingdept@gmail.com | I19: VIA GMAIL EMAILED AND CALLED 2/19/2026
A20: private | B20: J.C RODRIGUEZ CONSTRUCTION CORP | D20: purchasing.jcrcc@gmail.com | I20: VIA GMAIL EMAILED AND CALLED 2/19/2026
A21: private | B21: TOYO CONSTRUCTION CO. LTD | I21: VIA GMAIL EMAILED AND CALLED 2/19/2026
A22: private | B22: COORS CONSTRUCTION | D22: coors2207@yahoo.com | I22: VIA GMAIL EMAILED AND CALLED 2/20/2026
A23: private | B23: AB PAMATONG TRADING & CORPORATION | I23: VIA GMAIL EMAILED AND CALLED 2/20/2026
A24: mining company | B24: PHILLIPINE MINING DEVELOPMENT CORPORATION (PMDC) | D24: info@pmdc.com.ph | I24: VIA GMAIL EMAILED AND CALLED 2/20/2026
A25: mining company | B25: MARCVENTURES & DEVELOPMENT CORPORATION | D25: bernie.gamba@marcventures.com.ph
B26: TARGET FOR MARCH 2-6, 2026 | I26: Accomplishment | M26: Remarks
A27: private | B27: 4B CONSTRUCTION CORPORATION | I27: VIA GMAIL3/2/2026 ,VIBER EMAILED AND CALLED 3/2/2026-old client
A28: private | B28: HAUSLAND CONSTRUCTION (PAMPANGA) - | D28: 8531091/ Direct Inquiry (Engr. Sonny Bagang) viber 09178221592 | I28: VIA VIBER EMAILED AND CALLED 3/3/2026
A29: private | B29: FF CRUZ CONSTRUCTION | D29: 89273324/viber 09175649658 | I29: VIA VIBER EMAILED AND CALLED 3/3/2026 -old client
A30: private | B30: HILMARC'S CONSTRUCTION CORPORATION | D30: 86543911/86544153/ 09494567486
A31: private | B31: SINO ROAD AND BRIDGE | D31: (Mam Richelle Masanegra) viber 09512666493 | I31: VIA GMAIL 2/19/2026 ,VIBER EMAILED AND CALLED 3/3/2026 wala pang need as of now na goods inquiry nila total station repair
A32: private | B32: UNIVERSAL TESTING LABORATORY AND INSPECTION INC. PASIG | D32: 09956320368/86710909 /universaltesting2000@gmail.com | F32: JADC Compound, 7 Eulogio Rodriguez Jr. Ave, Pasig, 1600 Metro Manila | I32: VIA email gmail & called 3/4/2026
A33: private | B33: ACS MANUFACTURING INC | D33: 09266636300 MS.Jocelyn Gallardo/ j.galado@acs-manufacturing.com | F33: 38th floor ortigas global corporate center no.3 julia vargas avenue ortigas center pasig city | I33: VIA email gmail & called 3/4/2026 old client existing
C41: Company | D41: GEI QOUTATION # | E41: DATED | F41: AMOUNT | G41: AGENT | H41: REMARKS | I41: Marketing Coordinator | J41: NOTE
C46: LBS DIGITAL INFRASTRUCTURE CORP.
C47: MKGC
C48: MKGC
B49: CALIBRATION | C49: READYCON TRADING AND CONSTRUCTION CORP. | D49: GEI-CAL-2026-2307 | E49: 46080 | F49: 8500 | H49: With P.O | I49: Pau | J49: PO# 10110576
B50: GOODS | C50: READYCON TRADING AND CONSTRUCTION CORP. | D50: GEI-GDS-2026-12824 | E50: 46086 | F50: 40000 | G50: HOUSE | J50: WATERBATH FOR APPROVAL | K50: for revised
B51: GOODS | C51: VINES CONSTRUCTION | D51: GEI-GDS-2026-12822A | E51: 46085 | F51: 105982.14 | G51: HOUSE | J51: FOR APPROVAL | K51: mas mababa offer ni testmark
B52: GOODS | C52: FOUR POINT BUILDERS | D52: GEI-GDS-2026-12817 | E52: 46085 | F52: 304640 | G52: HOUSE | J52: FOR APPROVAL
B53: GOODS | C53: PHOENIX ASPHALT PHILIPPINES,INC. | D53: GEI-GDS-2026 - 12816 | E53: 46084 | F53: 70000 | G53: HOUSE | J53: THERMOMETER 4 PCS NA IPR NA WAITING NALANG FOR APPROVAL | K53: 3/3/2026 Last update
B54: Goods | C54: 4B CONSTRUCTION CORPORATION | D54: GEI-GDS-2026-12813 | E54: 46084 | F54: 350000 | G54: HOUSE | H54: FOR APPROVAL PA | J54: COMPRESSION For approval pa | K54: 3/5/2026 last call
B55: Goods | C55: SOIL PHILIPPINE TESTING INC. | D55: GEI-GDS-2026-12780 | E55: 46076 | F55: 5000 | G55: HOUSE | H55: to ff up | I55: Pau | J55: P.O 2026-019
B56: Goods | C56: HYUNDAI ENGINEERING & CONSTRUCTION | D56: GEI-GDS-2026-12796 | E56: 46078 | F56: 277400 | H56: no stocks item for nl natatagalan sa lead time and sa calcium carbide double the price daw ang presyo naten as per client | J56: NEGATIVE
...

Sheet OLD RECORDS AGENTS HANDLE
A1: P.O DATE | B1: AGENT | C1: Client Company Name | D1: GOVT /PRIVATE | E1: GOODS/ CALIBRATION | F1: Amount | G1: P.O reference | H1: SERVED /NOT SERVED | I1: Principal | J1: Item Description /Inquiry of Goods/ Services | K1: BIR/COR | L1: ADDRESS | M1: Contact No. | N1: Contact Person | O1: Qoutation Control No. | P1: SALES INVOICE | Q1: SALES INVOICE DATE | R1: DR | S1: PAYMENT TERMS | T1: REMARKS | U1: Qoutation Control No. | V1: Amount | W1: NOA DATE | X1: NTP DATE | Y1: CONTRACT
A8: 45406 | B8: DOM | C8: HONGHUI PIONEER S-CEMENT INTERNATIONAL INC. | D8: PRIVATE | E8: GOODS | F8: 644632.5 | G8: 1294 | J8: Blaine air,Cement Autoclave, Two Gang Prism Mould, Filter Paper,Vicat Apparatus | L8: UNIT 404 DHI BLDG., 2 LAPU LAPU AVE., MAGALLANES MAKATI CITY
A9: 45391 | B9: DOM | C9: ENGR JOVY NOTARIO | D9: PRIVATE | E9: GOODS | F9: 250000 | G9: QT SERVED AS P.O | J9: Rebar Scanner
A10: 45408 | B10: DOM | C10: CALMARLAND | D10: PRIVATE | E10: GOODS | F10: 28000 | G10: #2024040433 | I10: nl scientific | J10: Rebound Hammer | L10: Maharlika Highway, Kanlurang Mayao, Lucena City | M10: (042) 373-3001
A11: 45425 | B11: DOM | C11: Wizard Construction | D11: PRIVATE | E11: GOODS | F11: 17000 | G11: PO24-017 | J11: FDT | L11: Nueva Ecija | M11: ENGR JEREMY
A12: 45483 | B12: DOM | C12: JS HARDIN | D12: PRIVATE | E12: GOODS | F12: 43700 | G12: GEI-GDS-2024-11152 | J12: VARIOUS LOCAL | L12: FOR DPWH
A13: JULY | B13: DOM | C13: SMART COMPANY MASONRY PHILIPPINES INC | D13: PRIVATE | E13: GOODS | F13: 65470 | G13: PO NO. 2022-0905 | J13: SIEVES | L13: 688 INDUSTRIAL MEGA CITY HIGHWAY TAYTAY RIZAL | M13: 863-09961
A14: 45492 | B14: DOM | C14: JS HARDIN | D14: PRIVATE | E14: GOODS | F14: 35200 | G14: GEI-GDS-2024-1632 | J14: BALANCE AND SIEVES | L14: 5TH FLOOR BLDG 135 DELA ROSA ST. LEGASPI VILLAGE MAKATI CITY
A15: 45491 | B15: DOM | C15: ROPALILAND | D15: PRIVATE | E15: GOODS | F15: 15361.61 | G15: ROPALILAND-2024-0001711 | J15: LOCAL ITEMS | L15: ROPALI PLAZA ESCRIVA DRIVE COR GOLDLOOP BRGY SAN ANTONIO PASIG CITY
A16: 45509 | B16: DOM | C16: ALTEO | D16: PRIVATE | E16: GOODS | F16: 3400 | G16: 2024-007 | J16: LA MACHINE
A17: 45558 | B17: DOM | C17: CALMARLAND | D17: PRIVATE | E17: GOODS | F17: 56000 | G17: #2024090415 | I17: nl scientific | J17: Rebound Hammer | L17: Maharlika Highway, Kanlurang Mayao, Lucena City | M17: (042) 373-3001
A18: 45559 | B18: DOM | C18: CAPARAL APPLIANCES AND FURNITURES | D18: PRIVATE | E18: GOODS | F18: 113950 | G18: CAP-A1901034 | J18: Various | L18: Km 29 Emilio Aguinaldo Hi-way brgy Salitran 2 Dasmarinas Cavite
A19: 45555 | B19: DOM | C19: HONGHUI PIONEER S-CEMENT INTERNATIONAL INC. | D19: PRIVATE | E19: GOODS | F19: 9986.88 | G19: 1532 | J19: Various | L19: UNIT 404 DHI BLDG., 2 LAPU LAPU AVE., MAGALLANES MAKATI CITY
A20: 45568 | B20: DOM | C20: ALTEO | D20: PRIVATE | E20: GOODS | F20: 18100 | G20: 2024008 | J20: Various | L20: LTO Compound Brgy.1 Calamba City, Laguna
A21: 45492 | B21: DOM | C21: JS HARDIN | D21: PRIVATE | E21: GOODS | F21: 6000 | G21: GEI-GDS-2024-1632 | J21: OVEN | L21: 5TH FLOOR BLDG 135 DELA ROSA ST. LEGASPI VILLAGE MAKATI CITY
A22: 45587 | B22: DOM | C22: GUAGUA NATIONAL COLLEGES INC. | D22: PRIVATE | E22: GOODS | F22: 251000 | G22: NO.0202 | J22: LOCAL ITEMS | L22: GUAGUA PAMPANGA
A23: 45617 | B23: DOM | C23: BORGE ENGINEERING OFFICE | D23: PRIVATE | E23: GOODS | F23: 116500 | G23: GEI-GDS-2024-11529 | J23: Rebound Hammer | L23: Tagum City | M23: 09650855636/Charmainewines@gmail.com
A24: 45705 | B24: DOM | C24: Summit Sigma ready mix concrete corporation | D24: PRIVATE | E24: Calibration | F24: 10000 | G24: EPO12821 | I24: nl scientific | J24: Compression Machine
A25: 45694 | B25: DOM | C25: CMSE ENGINEERING SERVICES | D25: PRIVATE | E25: GOODS | F25: 28500 | G25: GEI-GDS-2024-11799 | I25: nl scientific | J25: Liquid Limit Apparatus | L25: Brgy.Tanza Boac Marinduque | M25: 09063132611 / cmseengineeringservices@gmail.com
A26: 45994 | B26: DOM | C26: GROUNDTEK GEOTECHNICAL TESTING SERVICES | D26: PRIVATE | E26: GOODS | F26: 120000 | G26: P.O NO. 20250312-01 | J26: LA MACHINE | L26: 26 ALMA JOSE BRGY 177 CALOOCAN CITY | M26: 92182657858
A27: 45773 | B27: DOM | C27: RRA ELECTRICAL AND INDUSTRIAL SUPPLIESS TRADING | D27: PRIVATE | E27: GOODS | F27: 37800 | L27: BARANGAY 1, 8501 SAN FRANCISCO AGUSAL DEL SUR
A28: 45768 | B28: DOM | C28: COTECNA | D28: PRIVATE | E28: GOODS | F28: 108000 | G28: GEI-GDS-2024-11869 | L28: UNIT 704 7TH FLOOR ASIAN STAR BLDG ASEAN DRIVE COR.SINGAPURA LANE, FILINVEST CORPORATE CITY ALABANG MUNTINLUPA
A29: 45509 | B29: DOM | C29: ALTEO | D29: PRIVATE | E29: GOODS | F29: 71000 | G29: 2025001 | I29: LOCAL | J29: VARIOUS
A30: 45803 | B30: DOM | C30: ALTEO | D30: PRIVATE | E30: GOODS | F30: 40000 | G30: 2025002 | I30: LOCAL | J30: VARIOUS
A31: 45846 | B31: DOM | C31: REPUBLIC CEMENT MINDANAO INC., | D31: PRIVATE | E31: Calibration | F31: 103040 | G31: OP47000980 | L31: BGC
A32: 45828 | C32: JAKT BUILDERS INC. | D32: PRIVATE | E32: GOODS | F32: 332100 | G32: GEI-GDS-2025-12054A | J32: VARIOUS
A33: 45790 | B33: DOM | C33: SUBIC BAY METROPOLITAN AUTHORITY | D33: PRIVATE | E33: GOODS | F33: 95000 | G33: GEI-GDS-2025-11863 | J33: VARIOUS | L33: SUBIC ANGELES CITY
A34: 45887 | B34: DOM | C34: JS HARDIN | D34: PRIVATE | E34: GOODS | F34: 25000 | G34: GEI-GDS-2024-12249 | J34: SIEVES | L34: 5TH FLOOR BLDG 135 DELA ROSA ST. LEGASPI VILLAGE MAKATI CITY
A35: 45896 | C35: VCO CONSTRUCTION AND SUPPLY | D35: PRIVATE | F35: 100000 | L35: NORTHERN SAMAR
A36: 45925 | C36: STA CLARA INTERNATIONAL | D36: PRIVATE | F36: 96000
A37: 45674 | B37: DOMINIC | C37: DOST-ITDI | D37: GOV'T | F37: 3595000 | G37: GIAE-PO-2025-01-0013 (MSD) | J37: PASTE EXTRUSION 3D PRINTER SYSTEM | L37: DOST-ITDI- DOST Compound,General Santos Ave., Bicutan,Taguig City | R37: DR DATE:1/2/2025
B42: DPWH-Isabela 4th DEO | C42: 24GBH09 | D42: GOV'T | F42: 4000140 | H42: Various | L42: DPWH-Isabela 4th DEO REGIONAL OFFICE II Quezon, San Isidro,Isabela | W42: 45442 | X42: 45446
A43: 45532 | B43: DPWH-Iloilo City | C43: 24GG021 | D43: GOV'T | F43: 12995000 | G43: 24-08-80 | H43: drilling machine | L43: DPWH-6th Regional Office Fort San Pedro,Iloilo City | W43: ✔ | X43: 45537
A44: 05/24/2024 | B44: DPWH -Pampanga 2nd D.E.O., | C44: 24GCH022 | D44: GOV'T | F44: 2403000 | G44: 2024-05-021 | H44: Various | L44: DPWH -Pampanga 2nd D.E.O., San Antonio, Guagua Pampanga | W44: 45427 | X44: 45439 | Y44: 7 Days after receipt of p.o
A45: 08/08/2024 | B45: DPWH Davao Del Norte Sub-Deo | C45: 24GL0018 | D45: GOV'T | F45: 11123000 | G45: 2024-08-138 DDNS | H45: drilling machine | L45: DPWH Davao Del Norte Sub-Deo Tagum City,Region XI | W45: 45496 | Y45: 90 CD
A46: 45308 | B46: DPWH Davao Del Norte Sur DEO | C46: 23GLD0050 | D46: GOV'T | F46: 1028075 | G46: 24-01-010 | H46: drilling machine accessories | L46: DPWH Davao Del Sur DEO Digos City, Davao Del Sur | W46: 45288 | X46: 45309
A47: 45274 | B47: DPWH-Isabela 2ND DEO | C47: 23GBF09 | D47: GOV'T | F47: 2235000 | G47: 2023-12-0061-Proc/PO | H47: Various | L47: DPWH-Isabela 2ND DEO, Roxas, Isabela | W47: 45273 | X47: 45274 | Y47: 45 Cd

Sheet Sheet2
A1: P.O DATE | B1: AGENT | C1: Client Company Name | D1: GOVT /PRIVATE | E1: GOODS/ CALIBRATION | F1: Amount | G1: P.O reference | H1: SERVED /NOT SERVED | I1: Principal | J1: Item Description /Inquiry of Goods/ Services | K1: BIR/COR | L1: ADDRESS | M1: Contact No. | N1: Contact Person | O1: Qoutation Control No. | P1: SALES INVOICE | Q1: SALES INVOICE DATE | R1: DR | S1: PAYMENT TERMS | T1: REMARKS | U1: Qoutation Control No. | V1: Amount | W1: NOA DATE | X1: NTP DATE | Y1: CONTRACT
A5: 45678 | B5: BTC | C5: RFAELDAN CONSTRUCTION SERVICES CO. | D5: PRIVATE | E5: GOODS | F5: 36000 | G5: 2025/018
A6: 45670 | B6: BTC | C6: NOBLE EQUIPMENT INC | D6: PRIVATE | E6: GOODS | F6: 64100 | G6: 250101
A7: 45663 | B7: BTC | C7: MEGA SOUTHERN ASPHALT MIX CORP | D7: PRIVATE | E7: GOODS | F7: 65700 | G7: 2501-0005540
A8: 45673 | B8: BTC | C8: MEGA SOUTHERN ASPHALT MIX CORP | D8: PRIVATE | E8: GOODS | F8: 14000 | G8: 2501-0005596
A9: 45664 | B9: BTC | C9: HUAYOU CONSTRUCTION DEVELOPMENT PHILIPPINES CORPORATION | D9: PRIVATE | E9: GOODS | F9: 116700 | G9: HCDPC-PO-BSPP-1224-11235
A10: 45583 | B10: BTC | C10: SYCUIN COATING & WIRES, INC | D10: PRIVATE | E10: GOODS | F10: 41750 | G10: 36810
A11: 45674 | B11: BTC | C11: ERODMA READY-MIX CONCRETE CO | D11: PRIVATE | E11: CALIBRATION | F11: 2000 | G11: 4311
A12: 45665 | B12: BTC | C12: UNIVERSAL TESTING LABORATORY & INSPECTION INC | D12: PRIVATE | E12: CALIBRATION | F12: 5000 | G12: GEI-CAL-2025-1790
A13: 45611 | B13: HOUSE | C13: XWELL | D13: PRIVATE | E13: GOODS | F13: 430000 | G13: PO24-00067
A14: 45643 | C14: SAINT GOBAIN PHILIPPINES CO. LTD., INC. | D14: PRIVATE | E14: GOODS | F14: 414000 | G14: 2401279
A15: 45679 | C15: GEOSERVICES PHILIPPINES CORPOARATION | D15: PRIVATE | E15: GOODS | F15: 115000 | G15: GSPC-2025-001
A16: 45673 | C16: PHILSOUTH BUILDERS INC. | D16: PRIVATE | E16: GOODS | F16: 72000 | G16: 90427
A17: 45670 | C17: TOYO-SHIMIZU JOINT VENTURE | D17: PRIVATE | E17: GOODS | F17: 1500 | G17: PRP4-2501-065
A18: 45678 | C18: J.E MANALO | D18: PRIVATE | E18: GOODS | F18: 24000 | G18: JEM-PO 002042
J28: 1056500
B30: SERVICES
A31: 45685 | B31: CVN PHILIPPINES CONSTRUCTION INC. | G31: 36000 | H31: CVN-BAUER-20250115
A32: 45687 | B32: 3DESIE COMMERCIAL & INDUSTRIAL CORP. | G32: 4500 | H32: 2025-0130-005
A33: 45671 | B33: 3DESIE COMMERCIAL & INDUSTRIAL CORP. | G33: 31000 | H33: 2025-0114-003
A34: 45665 | B34: READYCON TRADING AND CONST. CORP. | G34: 6500 | H34: PO 10097696
A35: 45678 | B35: SUPERMIX REDI CONCRETE INC. | G35: 29000 | H35: B10073506
A36: 45668 | B36: RAYMAN BUILDERS, INC. | G36: 4500 | H36: 26696
A37: 45993 | B37: ITDI | G37: 13125 | H37: GAA-WO-202412-0292(STD)
A38: 45665 | B38: UNICORN METAL CORPORATION | G38: 15000 | H38: GEI-CAL-2025-1791
A39: 45661 | B39: TRI-PHIL INTERNATIONAL, INC. | G39: 15000 | H39: P25-00016
A40: 45681 | B40: ALPHA ONE A1 | G40: 18000 | H40: PO-GEI-A1007
A41: 45679 | B41: MEGAWIDE CONSTRUCTION CORPORATION | G41: 14500 | H41: JO 700019369
A42: 45679 | B42: MEGAWIDE CONSTRUCTION CORPORATION | G42: 26500 | H42: JO 700019369
A43: 45664 | B43: LATICRETE PHILIPPINES, INC. | G43: 13500 | H43: 104491 | J43: 227125
A46: Prepared by: JULIE C. CARIAGA
A48: PRIVATE | G48: AMOUNT | I48: P.O NUMBER
B49: Goods
A50: 45680 | B50: LR MARKETING | G50: 39350 | I50: LR-PO-2025-00038
A51: 45687 | B51: LR MARKETING | G51: 7000 | I51: LR-PO-2025-00040
A52: 45687 | B52: GASCON GEOTECHNICAL TESTING SERVICES | G52: 20000 | I52: GEI-GDS-2025-11669
A53: 45665 | B53: LR MARKETING | G53: 497000 | I53: LR-PO-2025-00037
A54: 45664 | B54: BMQ BUILDERS AND SUPPLY CORP. | G54: 343900 | I54: BMQ-02147
A55: 45681 | B55: GASCON GEOTECHNICAL TESTING SERVICES | G55: 978145 | I55: GEI-GDS-2025-11653
A56: 45665 | B56: MANUEL S. ENVERGA | G56: 8180 | I56: 150003995 | K56: 1893575
...
